Workbook

Sheet Sheet1
A1: CITY | B1: Name | C1: TỈNH | D1: Nhóm
A2: T. Bình Dương | B2: Binh Duong | C2: =_xlfn.XLOOKUP(A2,Raw!B:B,Raw!A:A) -> TỈNH BÌNH DƯƠNG | D2: =_xlfn.XLOOKUP(A2,Raw!B:B,Raw!C:C) -> 11
A3: T. Ninh Thuận | B3: Ninh Thuan | C3: =_xlfn.XLOOKUP(A3,Raw!B:B,Raw!A:A) -> TỈNH NINH THUẬN | D3: =_xlfn.XLOOKUP(A3,Raw!B:B,Raw!C:C) -> 10
A4: T. Đồng Nai | B4: Dong Nai | C4: =_xlfn.XLOOKUP(A4,Raw!B:B,Raw!A:A) -> TỈNH ĐỒNG NAI | D4: =_xlfn.XLOOKUP(A4,Raw!B:B,Raw!C:C) -> 12
A5: T. Tây Ninh | B5: Tay Ninh | C5: =_xlfn.XLOOKUP(A5,Raw!B:B,Raw!A:A) -> TỈNH TÂY NINH | D5: =_xlfn.XLOOKUP(A5,Raw!B:B,Raw!C:C) -> 11
A6: T. Lâm Đồng | B6: Lam Dong | C6: =_xlfn.XLOOKUP(A6,Raw!B:B,Raw!A:A) -> TỈNH LÂM ĐỒNG | D6: =_xlfn.XLOOKUP(A6,Raw!B:B,Raw!C:C) -> 9
A7: T. Bà Rịa - Vũng Tàu | B7: Ba Ria - Vung Tau | C7: =_xlfn.XLOOKUP(A7,Raw!B:B,Raw!A:A) -> TỈNH BÀ RỊA - VŨNG TÀU | D7: =_xlfn.XLOOKUP(A7,Raw!B:B,Raw!C:C) -> 12
A8: T. Bình Phước | B8: Binh Phuoc | C8: =_xlfn.XLOOKUP(A8,Raw!B:B,Raw!A:A) -> TỈNH BÌNH PHƯỚC | D8: =_xlfn.XLOOKUP(A8,Raw!B:B,Raw!C:C) -> 11
A9: T. Bình Thuận | B9: Binh Thuan | C9: =_xlfn.XLOOKUP(A9,Raw!B:B,Raw!A:A) -> TỈNH BÌNH THUẬN | D9: =_xlfn.XLOOKUP(A9,Raw!B:B,Raw!C:C) -> 10
A10: TP. Hồ Chí Minh | B10: TP. Ho Chi Minh | C10: =_xlfn.XLOOKUP(A10,Raw!B:B,Raw!A:A) -> TP. HỒ CHÍ MINH | D10: =_xlfn.XLOOKUP(A10,Raw!B:B,Raw!C:C) -> 11
A11: T. Khánh Hòa | B11: Khanh Hoa | C11: =_xlfn.XLOOKUP(A11,Raw!B:B,Raw!A:A) -> TỈNH KHÁNH HÒA | D11: =_xlfn.XLOOKUP(A11,Raw!B:B,Raw!C:C) -> 10
A12: T. Phú Yên | B12: Phu Yen | C12: =_xlfn.XLOOKUP(A12,Raw!B:B,Raw!A:A) -> TỈNH PHÚ YÊN | D12: =_xlfn.XLOOKUP(A12,Raw!B:B,Raw!C:C) -> 8
A13: T. Bình Định | B13: Binh Dinh | C13: =_xlfn.XLOOKUP(A13,Raw!B:B,Raw!A:A) -> TỈNH BÌNH ĐỊNH | D13: =_xlfn.XLOOKUP(A13,Raw!B:B,Raw!C:C) -> 8
... A64: T. ĐẮK NÔNG | B64: Dak Nong | C64: =_xlfn.XLOOKUP(A64,Raw!B:B,Raw!A:A) -> TỈNH ĐẮK NÔNG | D64: =_xlfn.XLOOKUP(A64,Raw!B:B,Raw!C:C) -> 9

Sheet LatLong
A1: Phân loại | B1: Tên Tắt | C1: Tên | D1: DC name | E1: Mã DC | F1: DC_Number | G1: Mã DC_CT | H1: Địa chỉ | I1: Tọa độ (kinh độ, vĩ độ) | J1: Diện tích | K1: Latitude | L1: Longitude
A2: DC | B2: Bình Thuận | C2: Trung Tâm Phân Phối Bình Thuận | D2: 07. Bình Thuận | E2: MTV | F2: 8155001 | G2: VHD | H2: Thôn Vĩnh Sơn, xã Vĩnh Hảo, Tỉnh Lâm Đồng | I2: 11°16'37.5"N 108°44'04.2"E | J2: 6050 | K2: 11.277083 | L2: 108.7345
A3: DC | B3: Cần Thơ | C3: Trung tâm Phân phối Cần Thơ | D3: 13. Hậu Giang Foods | E3: MDQ | F3: 8169001 | G3: FHG | H3: Kho Mekong, KCN Sông Hậu- Giai đoạn 1, xã Châu Thành, TP. Cần Thơ | I3: 9°57'53.1"N 105°50'57.9"E | J3: 4770 | K3: 9.96475 | L3: 105.84942
A4: DC | B4: Đà Nẵng | C4: Trung Tâm Phân Phối Đà Nẵng | D4: 06. Đà Nẵng | E4: MTN | F4: 8156001 | G4: DND | H4: Kho Kim Thành Lợi, Đường Số 9, KCN Hòa Khánh, Phường Liên Chiểu, TP. Đà Nẵng | I4: 16°05'06.0"N 108°08'25.5"E | J4: 3600 | K4: 16.085 | L4: 108.14042
A5: DC | B5: NM Net | C5: Trung tâm Phân phối Đồng Nai | D5: 12. NETCO | E5: NEU | F5: 8167001 | G5: NET | H5: Đường D4, KCN Lộc An - Bình Sơn, Xã Long Thành, Tỉnh Đồng Nai | I5: 10°47'12.5"N 106°59'29.8"E | J5: 12943 | K5: 10.786806 | L5: 106.99161
A6: DC | B6: Hải Dương | C6: Trung Tâm Phân Phối Hải Dương | D6: 01. Hải Dương | E6: MTS | F6: 8157001 | G6: HDD | H6: Km 48+450, Quốc Lộ 5, Phường Việt Hòa, Thành Phố Hải Phòng | I6: 20°56'20.4"N 106°17'42.1"E | J6: 8196 | K6: 20.939 | L6: 106.29503
A7: DC | B7: Hải Phòng | C7: Trung tâm Phân phối Hải Phòng | D7: 05. Hải Phòng | E7: MDV | F7: 8170001 | G7: HPD | H7: Cổng 3 cảng nội địa hải dương, Km 48+450 Quốc lộ 5, Phường Việt Hòa, Thành phố Hải Phòng | I7: 20°49'10.0"N 106°46'39.4"E | J7: 5880 | K7: 20.819444 | L7: 106.77761
A8: DC | B8: Hậu Giang Beer | C8: Trung Tâm Phân Phối Hậu Giang | D8: 14. Hậu Giang Beer | E8: MBG | F8: 8158001 | G8: BHG | H8: Khu Công Nghiệp Sông Hậu, Xã Châu Thành , Thành phố Cần Thơ | I8: 9°57'53.2"N 105°50'32.9"E | J8: 1000 | K8: 9.964778 | L8: 105.84247
A9: DC | B9: Hưng Yên | C9: Trung Tâm Phân Phối Hưng Yên | D9: 02. Hưng Yên | E9: MTH | F9: 8159001 | G9: HYD | H9: V3W8+MFV, Xã Tân Lập, tỉnh Hưng Yên | I9: 20.89694354346599, 106.06626012649295 | J9: 6023.36 | K9: 20.896944 | L9: 106.06626
A10: DC | B10: Thành Huy - Hưng Yên | C10: Trung Tâm Phân Phối Hưng Yên | D10: 02. Hưng Yên | E10: MTH | F10: 8159001 | G10: HYD | H10: Kho HY: nằm trong Cty Dịch Vụ Logictis Thành Huy - Q.Lộ 5A, Phường Đường Hào, Hưng Yên | I10: 20°55'45.0"N 106°04'02.2"E | J10: 15196 | K10: 20.929167 | L10: 106.06728
A11: DC | B11: Đông Dương - Hưng Yên | C11: Trung Tâm Phân Phối Hưng Yên | D11: 02. Hưng Yên | E11: MTH | F11: 8159001 | G11: HYD | H11: Thôn Tử Cầu, Xã Nguyễn Văn Linh, tỉnh Hưng Yên | I11: 20.954388190162952, 106.00570588741586 | J11: 5000 | K11: 20.954388 | L11: 106.00571
A12: DC | B12: Nghệ An | C12: Trung Tâm Phân Phối Nghệ An | D12: 03. Nghệ An | E12: MTA | F12: 8160001 | G12: NAD | H12: Khu A, Khu Nam Cấm, Khu Kinh Tế Đông Nam, Xã Trung Lộc, Nghệ An | I12: 18°49'42.5"N 105°39'24.7"E | J12: 15400 | K12: 18.828472 | L12: 105.65686
A13: DC | B13: Phú Yên | C13: Trung Tâm Phân Phối Phú Yên | D13: 09. Phú Yên | E13: MBN | F13: 8161001 | G13: BPY | H13: Lô A12 - A14 Khu công nghiệp Hòa Hiệp, Phường Hòa Hiệp, Đắk Lắk | I13: 13°00'43.3"N 109°21'52.7"E | J13: 1000 | K13: 13.011972 | L13: 109.36464
... A16: DC | B16: Kerry | C16: Trung Tâm Phân Phối Sóng Thần - Inhouse | D16: 08. Kerry | E16: MTD | F16: 8163001 | G16: STD | H16: Kho số 1, Tổng kho Kerry, đường số 18, KCN Sóng Thần 2, Phường Dĩ An, TPHCM | I16: 10°53'24.7"N 106°44'03.6"E | J16: 28984 | K16: 10.890194 | L16: 106.73433
A17: DC | B17: Suối Mơ | C17: Trung Tâm Phân Phối Suối Mơ | E17: SMD | F17: 8165001 | G17: SMD | H17: Tổ 5, khu 8, P. Bãi Cháy, T. Quảng Ninh | I17: 20°57'38.9"N 107°01'40.1"E | J17: 730 | K17: 20.960806 | L17: 107.02781
A18: DC | B18: Tanimex - Tân Bình | C18: Trung Tâm Phân Phối Tân Bình | D18: 11. Tân Bình | E18: MTF | F18: 8166001 | G18: HCM | H18: Kho xưởng lô 1-6, Cụm 1, Đường M14, KCN Tân Bình, Phường Bình Hưng Hòa, TPHCM | I18: 10°49'14.4"N 106°36'50.7"E | J18: 7700 | K18: 10.820667 | L18: 106.61408
A19: DC | B19: Miền Núi - Tân Bình | C19: Trung Tâm Phân Phối Tân Bình | D19: 11. Tân Bình | E19: MTF | F19: 8166001 | G19: HCM | H19: Lô III 14, Đường số 1, Nhóm CN III, KCN Tân Bình, Phường Tây Thạnh, TPHCM | I19: 10.820919510037575, 106.61709947035497 | J19: 250 | K19: 10.82092 | L19: 106.6171
A20: DC | B20: Việt Tiến - Tân Bình | C20: Trung Tâm Phân Phối Tân Bình | D20: 11. Tân Bình | E20: MTF | F20: 8166001 | G20: HCM | H20: Lô III-10 Nhóm KCN III, KCN Tân Bình, Phường Tây Thạnh, TPHCM | I20: 10.820919510037575, 106.61709947035497 | J20: 570 | K20: 10.82092 | L20: 106.6171
A21: DC | B21: Vân Trúc | C21: Trung tâm phân phối Vân Trúc | D21: 08.1. Kho Vân Trúc | E21: MTD | F21: 8171001 | G21: STD | H21: 100/1G Khu Phố Đồng An 2, Phường Bình Hòa, TPHCM | I21: 10.898892302150536, 106.72275468517746 | J21: 3850 | K21: 10.898892 | L21: 106.72276
A22: DC | B22: BW | C22: Trung tâm phân phối BW | D22: 08.2. Kho BW | E22: MTD | G22: STD | J22: 3850 | K22: 10.898892 | L22: 106.72276
A23: DC | B23: Đồng Nai | D23: 15. Đồng Nai | G23: DN2 | H23: VX24+662, Long Đức, Long Thành, Đồng Nai, Vietnam | I23: 10.851160102363028, 106.95547296357032 | K23: 10.85116 | L23: 106.95547
A24: DC | C24: An Bình DCs | G24: ABD | H24: An Bình, Thành phố Biên Hòa, Đồng Nai | I24: 10.919767850139456, 106.85998435794458 | K24: 10.919768 | L24: 106.85998
A25: DC | C25: Kho MML - Hà Nam | G25: HYM | H25: Đại Cương, Kim Bảng, Hà Nam | I25: 20.636496060714716, 105.88530447418114 | K25: 20.636496 | L25: 105.8853
A26: DC | C26: Kho MML - Long An | G26: LAM | H26: Khu Công Nghiệp Tân Đức, Xã Hựu Thành, Huyện Đức Hòa, Tỉnh Long An | I26: 10.783012788829994, 106.46042287671807 | K26: 10.783013 | L26: 106.46042
A27: Factory | C27: Nhà máy Quang Hanh | G27: QNW | H27: Km9, Phường Quang Hanh, Thị Xã Cẩm Phả, Tỉnh Quảng Ninh | I27: 21.0082107, 107.2271147 | K27: 21.0082107 | L27: 107.2271147
A28: Factory | C28: Nhà máy Suối Mơ | G28: SMW | H28: Tổ 5, Khu 8, Phường Bãi Cháy, TP. Hạ Long, Tỉnh Quảng Ninh | I28: 20.9578941, 107.0832118 | K28: 20.9578941 | L28: 107.0832118
A29: Factory | C29: Nhà máy Hải Dương | G29: MHD | H29: Lô 22, KCN Đại An, TP. Hải Dương, Tỉnh Hải Dương | I29: 20.9297632, 106.2669247 | K29: 20.9297632 | L29: 106.2669247
A30: Factory | C30: Nhà máy gia công MSJ tại MHN | G30: MCN | H30: Lô CN-02, KCN Đồng Văn IV, Kim Bảng, Hà Nam | I30: 20.6378553, 105.8885067 | K30: 20.6378553 | L30: 105.8885067
A31: Factory | C31: Nhà máy sữa Elovi | G31: ELO | H31: KCN Nam Phổ Yên, Thuận Thành, Phổ Yên, Thái Nguyên | I31: 21.3340466, 105.8686921 | K31: 21.3340466 | L31: 105.8686921
A32: Factory | C32: Nhà máy Masan Miền Bắc | G32: MMB | H32: Khu B, Khu KT Đông Nam, Khu Công nghiệp Nam Cấm, xã Nghi Long, Huyện Nghi Lộc, tỉnh Nghệ An, Việt Nam | I32: 18.8333799, 105.6571789 | K32: 18.8333799 | L32: 105.6571789
A33: Factory | C33: Nhà máy Beer Phú Yên | G33: PYB | H33: Lô A12 - A14 - KCN Hòa Hiệp, Xã Hòa Hiệp Bắc, Huyện Đông Hòa, Tỉnh Phú Yên | I33: 13.013859, 109.3619624 | K33: 13.013859 | L33: 109.3619624
A34: Factory | C34: Nhà máy Vĩnh Hảo | G34: VHC | H34: Thôn Vĩnh Sơn, Xã Vĩnh Hảo, Huyện Tuy Phong, Tỉnh Bình Thuận | I34: 11.3132444, 108.7534139 | K34: 11.3132444 | L34: 108.7534139
A35: Factory | C35: Nhà máy Vĩnh Hảo B20L | G35: V20 | H35: Thôn Vĩnh Sơn, Xã Vĩnh Hảo, Huyện Tuy Phong, Tỉnh Bình Thuận | I35: 11.3132444, 108.7534139 | K35: 11.3132444 | L35: 108.7534139
A36: Factory | C36: Nhà máy VCF Biên Hòa | G36: VCF | H36: KCN Biên Hòa 1, Phường An Bình, TP. Biên Hòa, Tỉnh Đồng Nai | I36: 10.921125, 106.8613515 | K36: 10.921125 | L36: 106.8613515
A37: Factory | C37: Nhà máy VCF Long Thành | G37: VLT | H37: KCN Long Thành, Xã Tam An, Huyện Long Thành, Tỉnh Đồng Nai | I37: 10.8312488, 106.935861 | K37: 10.8312488 | L37: 106.935861
A38: Factory | C38: Nhà máy NET Long Thành | G38: NET | H38: Đường D4, KCN Lộc An - Bình Sơn, Xã Bình Sơn, Huyện Long Thành, Tỉnh Đồng Nai | I38: 10.7948211, 106.9900006 | K38: 10.7948211 | L38: 106.9900006
... A50: Factory | C50: Nhà máy gia công OCM tại Việt Nam | G50: OCM | H50: Đức Lập Hạ, Đức Hòa, Long An | I50: 10.9153529, 106.4409484 | K50: 10.9153529 | L50: 106.4409484
A51: Factory | C51: Sản phẩm nhập khẩu về tại DC | G51: IMP | H51: Sản phẩm nhập khẩu từ NCC
A52: Factory | C52: Nhà máy gia công Aroma | G52: ARM | H52: Đông Sơn, Huyện Thủy Nguyên, TP Hải Phòng | I52: 20.9376842, 106.6556575 | K52: 20.9376842 | L52: 106.6556575
A53: Factory | C53: Nhà máy gia công Godaco Bến Tre | G53: BTG | H53: Lô A19-20, KCN An Hiệp, xã Tường Đa, huyện Châu Thành, tỉnh Bến Tre | I53: 10.2797839, 106.3007738 | K53: 10.2797839 | L53: 106.3007738
...

Sheet Raw
A1: TỈNH LÀO CAI | B1: T. LÀO CAI | C1: 1
A2: TỈNH LAI CHÂU | B2: T. LAI CHÂU | C2: 1
A3: TỈNH ĐIỆN BIÊN | B3: T. ĐIỆN BIÊN | C3: 1
A4: TỈNH YÊN BÁI | B4: T. YÊN BÁI | C4: 1
A5: TỈNH SƠN LA | B5: T. SƠN LA | C5: 1
A6: TỈNH HÒA BÌNH | B6: T. HÒA BÌNH | C6: 5
A7: TỈNH HÀ GIANG | B7: T. HÀ GIANG | C7: 1
A8: TỈNH CAO BẰNG | B8: T. CAO BẰNG | C8: 2
A9: TỈNH LẠNG SƠN | B9: T. LẠNG SƠN | C9: 2
A10: TỈNH BẮC KẠN | B10: T. BẮC KẠN | C10: 2
A11: TỈNH THÁI NGUYÊN | B11: T. THÁI NGUYÊN | C11: 3
A12: TỈNH BẮC GIANG | B12: T. BẮC GIANG | C12: 3
... A63: TỈNH CÀ MAU | B63: T. CÀ MAU | C63: 14
